<?php
function inverse1($x) {
    if (!$x) {
        throw new Exception('Division by zero.');
    }
    return 1/$x;
}

try {
    echo inverse1(5) . "\n";
    echo inverse1(0) . "\n";
} catch (Exception $e) {
    echo 'Caught exception: ',  $e->getMessage(), "\n";
}

// Continue execution
echo "Hello World\n";
?>

<?php
function inverse($x) {
    if (!$x) {
        throw new Exception('Division by zero.');
    }
    return 1/$x;
}

try {
    echo inverse(5) . "\n";
    echo inverse(0) . "\n";
} catch (Exception $e) {
    echo 'Caught exception: ',  $e->getMessage(), "\n";
}

// Continue execution
echo "Hello World\n";
?>

<?php
function inverse2($x) {
    if (!$x) {
        throw new Exception('Division by zero.');
    }
    return 1/$x;
}

try {
    echo inverse2(5) . "\n";
} catch (Exception $e) {
    echo 'Caught exception: ',  $e->getMessage(), "\n";
} finally {
    echo "First finally.\n";
}

try {
    echo inverse2(0) . "\n";
} catch (Exception $e) {
    echo 'Caught exception: ',  $e->getMessage(), "\n";
} finally {
    echo "Second finally.\n";
}

// Continue execution
echo "Hello World\n";
?>
